[2024-07-02T11:33:23.875+0000] {taskinstance.py:1159} INFO - Dependencies all met for dep_context=non-requeueable deps ti=<TaskInstance: dag_with_python_dependencies_v05.get_hello scheduled__2024-07-01T03:20:00+00:00 [queued]>
[2024-07-02T11:33:23.901+0000] {taskinstance.py:1159} INFO - Dependencies all met for dep_context=requeueable deps ti=<TaskInstance: dag_with_python_dependencies_v05.get_hello scheduled__2024-07-01T03:20:00+00:00 [queued]>
[2024-07-02T11:33:23.901+0000] {taskinstance.py:1361} INFO - Starting attempt 1 of 1
[2024-07-02T11:33:23.947+0000] {taskinstance.py:1382} INFO - Executing <Task(PythonOperator): get_hello> on 2024-07-01 03:20:00+00:00
[2024-07-02T11:33:23.957+0000] {standard_task_runner.py:57} INFO - Started process 765 to run task
[2024-07-02T11:33:24.014+0000] {standard_task_runner.py:84} INFO - Running: ['***', 'tasks', 'run', 'dag_with_python_dependencies_v05', 'get_hello', 'scheduled__2024-07-01T03:20:00+00:00', '--job-id', '42', '--raw', '--subdir', 'DAGS_FOLDER/a_dependancy_check.py', '--cfg-path', '/tmp/tmptnk5ej3m']
[2024-07-02T11:33:24.038+0000] {standard_task_runner.py:85} INFO - Job 42: Subtask get_hello
[2024-07-02T11:33:24.227+0000] {task_command.py:415} INFO - Running <TaskInstance: dag_with_python_dependencies_v05.get_hello scheduled__2024-07-01T03:20:00+00:00 [running]> on host cce0ef517559
[2024-07-02T11:33:24.374+0000] {taskinstance.py:1660} INFO - Exporting env vars: AIRFLOW_CTX_DAG_OWNER='coder2j' AIRFLOW_CTX_DAG_ID='dag_with_python_dependencies_v05' AIRFLOW_CTX_TASK_ID='get_hello' AIRFLOW_CTX_EXECUTION_DATE='2024-07-01T03:20:00+00:00' AIRFLOW_CTX_TRY_NUMBER='1' AIRFLOW_CTX_DAG_RUN_ID='scheduled__2024-07-01T03:20:00+00:00'
[2024-07-02T11:33:24.377+0000] {taskinstance.py:1943} ERROR - Task failed with exception
Traceback (most recent call last):
  File "/opt/airflow/dags/a_dependancy_check.py", line 23, in get_hello
    connection = psycopg2.connect(user="docker",
  File "/home/airflow/.local/lib/python3.8/site-packages/psycopg2/__init__.py", line 122, in connect
    conn = _connect(dsn, connection_factory=connection_factory, **kwasync)
psycopg2.OperationalError: could not translate host name "posql-postgres_omor-1" to address: Name or service not known


During handling of the above exception, another exception occurred:

Traceback (most recent call last):
  File "/home/airflow/.local/lib/python3.8/site-packages/airflow/operators/python.py", line 192, in execute
    return_value = self.execute_callable()
  File "/home/airflow/.local/lib/python3.8/site-packages/airflow/operators/python.py", line 209, in execute_callable
    return self.python_callable(*self.op_args, **self.op_kwargs)
  File "/opt/airflow/dags/a_dependancy_check.py", line 273, in get_hello
    if connection:
UnboundLocalError: local variable 'connection' referenced before assignment
[2024-07-02T11:33:24.389+0000] {taskinstance.py:1400} INFO - Marking task as FAILED. dag_id=dag_with_python_dependencies_v05, task_id=get_hello, execution_date=20240701T032000, start_date=20240702T113323, end_date=20240702T113324
[2024-07-02T11:33:24.405+0000] {standard_task_runner.py:104} ERROR - Failed to execute job 42 for task get_hello (local variable 'connection' referenced before assignment; 765)
[2024-07-02T11:33:24.426+0000] {local_task_job_runner.py:228} INFO - Task exited with return code 1
[2024-07-02T11:33:24.449+0000] {taskinstance.py:2784} INFO - 0 downstream tasks scheduled from follow-on schedule check
