[2024-07-03T09:57:11.118+0000] {taskinstance.py:1159} INFO - Dependencies all met for dep_context=non-requeueable deps ti=<TaskInstance: reports_workflow.id_task_get_emails scheduled__2024-07-02T06:15:00+00:00 [queued]>
[2024-07-03T09:57:11.130+0000] {taskinstance.py:1159} INFO - Dependencies all met for dep_context=requeueable deps ti=<TaskInstance: reports_workflow.id_task_get_emails scheduled__2024-07-02T06:15:00+00:00 [queued]>
[2024-07-03T09:57:11.130+0000] {taskinstance.py:1361} INFO - Starting attempt 1 of 1
[2024-07-03T09:57:11.151+0000] {taskinstance.py:1382} INFO - Executing <Task(PythonOperator): id_task_get_emails> on 2024-07-02 06:15:00+00:00
[2024-07-03T09:57:11.161+0000] {standard_task_runner.py:57} INFO - Started process 20474 to run task
[2024-07-03T09:57:11.172+0000] {standard_task_runner.py:84} INFO - Running: ['***', 'tasks', 'run', 'reports_workflow', 'id_task_get_emails', 'scheduled__2024-07-02T06:15:00+00:00', '--job-id', '319', '--raw', '--subdir', 'DAGS_FOLDER/dag_email_robot.py', '--cfg-path', '/tmp/tmp89br6nip']
[2024-07-03T09:57:11.176+0000] {standard_task_runner.py:85} INFO - Job 319: Subtask id_task_get_emails
[2024-07-03T09:57:11.269+0000] {task_command.py:415} INFO - Running <TaskInstance: reports_workflow.id_task_get_emails scheduled__2024-07-02T06:15:00+00:00 [running]> on host 6f4ef5488251
[2024-07-03T09:57:11.409+0000] {taskinstance.py:1660} INFO - Exporting env vars: AIRFLOW_CTX_DAG_OWNER='FIRDAVS' AIRFLOW_CTX_DAG_ID='reports_workflow' AIRFLOW_CTX_TASK_ID='id_task_get_emails' AIRFLOW_CTX_EXECUTION_DATE='2024-07-02T06:15:00+00:00' AIRFLOW_CTX_TRY_NUMBER='1' AIRFLOW_CTX_DAG_RUN_ID='scheduled__2024-07-02T06:15:00+00:00'
[2024-07-03T09:57:11.410+0000] {logging_mixin.py:151} INFO - path of config file:  /opt/***
[2024-07-03T09:57:11.413+0000] {taskinstance.py:1943} ERROR - Task failed with exception
Traceback (most recent call last):
  File "/home/airflow/.local/lib/python3.8/site-packages/airflow/operators/python.py", line 192, in execute
    return_value = self.execute_callable()
  File "/home/airflow/.local/lib/python3.8/site-packages/airflow/operators/python.py", line 209, in execute_callable
    return self.python_callable(*self.op_args, **self.op_kwargs)
  File "/opt/airflow/dags/dag_email_robot.py", line 22, in get_emails
    email_conf = json.load (open(path / ("config/email_conf.json")))
NameError: name 'json' is not defined
[2024-07-03T09:57:11.422+0000] {taskinstance.py:1400} INFO - Marking task as FAILED. dag_id=reports_workflow, task_id=id_task_get_emails, execution_date=20240702T061500, start_date=20240703T095711, end_date=20240703T095711
[2024-07-03T09:57:11.436+0000] {standard_task_runner.py:104} ERROR - Failed to execute job 319 for task id_task_get_emails (name 'json' is not defined; 20474)
[2024-07-03T09:57:11.468+0000] {local_task_job_runner.py:228} INFO - Task exited with return code 1
[2024-07-03T09:57:11.498+0000] {taskinstance.py:2784} INFO - 0 downstream tasks scheduled from follow-on schedule check
[2024-07-03T12:04:46.315+0000] {taskinstance.py:1159} INFO - Dependencies all met for dep_context=non-requeueable deps ti=<TaskInstance: reports_workflow.id_task_get_emails scheduled__2024-07-02T06:15:00+00:00 [queued]>
[2024-07-03T12:04:46.333+0000] {taskinstance.py:1159} INFO - Dependencies all met for dep_context=requeueable deps ti=<TaskInstance: reports_workflow.id_task_get_emails scheduled__2024-07-02T06:15:00+00:00 [queued]>
[2024-07-03T12:04:46.335+0000] {taskinstance.py:1361} INFO - Starting attempt 1 of 1
[2024-07-03T12:04:46.355+0000] {taskinstance.py:1382} INFO - Executing <Task(PythonOperator): id_task_get_emails> on 2024-07-02 06:15:00+00:00
[2024-07-03T12:04:46.360+0000] {standard_task_runner.py:57} INFO - Started process 23294 to run task
[2024-07-03T12:04:46.367+0000] {standard_task_runner.py:84} INFO - Running: ['***', 'tasks', 'run', 'reports_workflow', 'id_task_get_emails', 'scheduled__2024-07-02T06:15:00+00:00', '--job-id', '761', '--raw', '--subdir', 'DAGS_FOLDER/dag_email_robot.py', '--cfg-path', '/tmp/tmpg3rj_pzx']
[2024-07-03T12:04:46.368+0000] {standard_task_runner.py:85} INFO - Job 761: Subtask id_task_get_emails
[2024-07-03T12:04:46.465+0000] {task_command.py:415} INFO - Running <TaskInstance: reports_workflow.id_task_get_emails scheduled__2024-07-02T06:15:00+00:00 [running]> on host 6f4ef5488251
[2024-07-03T12:04:46.582+0000] {taskinstance.py:1660} INFO - Exporting env vars: AIRFLOW_CTX_DAG_OWNER='FIRDAVS' AIRFLOW_CTX_DAG_ID='reports_workflow' AIRFLOW_CTX_TASK_ID='id_task_get_emails' AIRFLOW_CTX_EXECUTION_DATE='2024-07-02T06:15:00+00:00' AIRFLOW_CTX_TRY_NUMBER='1' AIRFLOW_CTX_DAG_RUN_ID='scheduled__2024-07-02T06:15:00+00:00'
[2024-07-03T12:04:46.583+0000] {logging_mixin.py:151} INFO - path of config file:  /opt/***
[2024-07-03T12:04:46.584+0000] {logging_mixin.py:151} INFO - #>2024-07-03 12:04:46.584182_User@StatDep: EmailRobot in screated.
[2024-07-03T12:04:46.584+0000] {logging_mixin.py:151} INFO - #>2024-07-03 12:04:46.584373_User@StatDep: get_for_recent_emails is started...
[2024-07-03T12:04:46.584+0000] {logging_mixin.py:151} INFO - #>2024-07-03 12:04:46.584510_User@StatDep: pop3_fetch_emails isstarted...
[2024-07-03T12:04:46.978+0000] {logging_mixin.py:151} INFO -    b'+OK'
[2024-07-03T12:04:47.393+0000] {logging_mixin.py:151} INFO -    mailbox have 1 emails and the robot can process 10
[2024-07-03T12:04:47.842+0000] {logging_mixin.py:151} INFO -    #>2024-07-03 12:04:47.842861_conneciton to db is set.
[2024-07-03T12:04:47.850+0000] {taskinstance.py:1943} ERROR - Task failed with exception
Traceback (most recent call last):
  File "/home/airflow/.local/lib/python3.8/site-packages/airflow/operators/python.py", line 192, in execute
    return_value = self.execute_callable()
  File "/home/airflow/.local/lib/python3.8/site-packages/airflow/operators/python.py", line 209, in execute_callable
    return self.python_callable(*self.op_args, **self.op_kwargs)
  File "/opt/airflow/dags/dag_email_robot.py", line 25, in get_emails
    robot.fetch_emails()
  File "/opt/airflow/dags/emailRobot.py", line 62, in fetch_emails
    return self.pop3_fetch_emails()
  File "/opt/airflow/dags/emailRobot.py", line 156, in pop3_fetch_emails
    cursor.execute (query, insert_values)
psycopg2.errors.UndefinedTable: relation "sma_stat_dep.tbl_file_upload" does not exist
LINE 1: ...) AS (INSERT INTO                                 sma_stat_d...
                                                             ^

[2024-07-03T12:04:47.868+0000] {taskinstance.py:1400} INFO - Marking task as FAILED. dag_id=reports_workflow, task_id=id_task_get_emails, execution_date=20240702T061500, start_date=20240703T120446, end_date=20240703T120447
[2024-07-03T12:04:47.880+0000] {standard_task_runner.py:104} ERROR - Failed to execute job 761 for task id_task_get_emails (relation "sma_stat_dep.tbl_file_upload" does not exist
LINE 1: ...) AS (INSERT INTO                                 sma_stat_d...
                                                             ^
; 23294)
[2024-07-03T12:04:47.917+0000] {local_task_job_runner.py:228} INFO - Task exited with return code 1
[2024-07-03T12:04:47.946+0000] {taskinstance.py:2784} INFO - 0 downstream tasks scheduled from follow-on schedule check
[2024-07-03T12:22:20.563+0000] {taskinstance.py:1159} INFO - Dependencies all met for dep_context=non-requeueable deps ti=<TaskInstance: reports_workflow.id_task_get_emails scheduled__2024-07-02T06:15:00+00:00 [queued]>
[2024-07-03T12:22:20.582+0000] {taskinstance.py:1159} INFO - Dependencies all met for dep_context=requeueable deps ti=<TaskInstance: reports_workflow.id_task_get_emails scheduled__2024-07-02T06:15:00+00:00 [queued]>
[2024-07-03T12:22:20.583+0000] {taskinstance.py:1361} INFO - Starting attempt 1 of 1
[2024-07-03T12:22:20.642+0000] {taskinstance.py:1382} INFO - Executing <Task(PythonOperator): id_task_get_emails> on 2024-07-02 06:15:00+00:00
[2024-07-03T12:22:20.647+0000] {standard_task_runner.py:57} INFO - Started process 24113 to run task
[2024-07-03T12:22:20.678+0000] {standard_task_runner.py:84} INFO - Running: ['***', 'tasks', 'run', 'reports_workflow', 'id_task_get_emails', 'scheduled__2024-07-02T06:15:00+00:00', '--job-id', '1037', '--raw', '--subdir', 'DAGS_FOLDER/dag_email_robot.py', '--cfg-path', '/tmp/tmpa_qsh2_9']
[2024-07-03T12:22:20.681+0000] {standard_task_runner.py:85} INFO - Job 1037: Subtask id_task_get_emails
[2024-07-03T12:22:20.782+0000] {task_command.py:415} INFO - Running <TaskInstance: reports_workflow.id_task_get_emails scheduled__2024-07-02T06:15:00+00:00 [running]> on host 6f4ef5488251
[2024-07-03T12:22:20.983+0000] {taskinstance.py:1660} INFO - Exporting env vars: AIRFLOW_CTX_DAG_OWNER='FIRDAVS' AIRFLOW_CTX_DAG_ID='reports_workflow' AIRFLOW_CTX_TASK_ID='id_task_get_emails' AIRFLOW_CTX_EXECUTION_DATE='2024-07-02T06:15:00+00:00' AIRFLOW_CTX_TRY_NUMBER='1' AIRFLOW_CTX_DAG_RUN_ID='scheduled__2024-07-02T06:15:00+00:00'
[2024-07-03T12:22:20.984+0000] {logging_mixin.py:151} INFO - path of config file:  /opt/***
[2024-07-03T12:22:20.984+0000] {logging_mixin.py:151} INFO - #>2024-07-03 12:22:20.984901_User@StatDep: EmailRobot in screated.
[2024-07-03T12:22:20.985+0000] {logging_mixin.py:151} INFO - #>2024-07-03 12:22:20.985121_User@StatDep: get_for_recent_emails is started...
[2024-07-03T12:22:20.985+0000] {logging_mixin.py:151} INFO - #>2024-07-03 12:22:20.985296_User@StatDep: pop3_fetch_emails isstarted...
[2024-07-03T12:24:31.390+0000] {taskinstance.py:1943} ERROR - Task failed with exception
Traceback (most recent call last):
  File "/home/airflow/.local/lib/python3.8/site-packages/airflow/operators/python.py", line 192, in execute
    return_value = self.execute_callable()
  File "/home/airflow/.local/lib/python3.8/site-packages/airflow/operators/python.py", line 209, in execute_callable
    return self.python_callable(*self.op_args, **self.op_kwargs)
  File "/opt/airflow/dags/dag_email_robot.py", line 25, in get_emails
    robot.fetch_emails()
  File "/opt/airflow/dags/emailRobot.py", line 62, in fetch_emails
    return self.pop3_fetch_emails()
  File "/opt/airflow/dags/emailRobot.py", line 77, in pop3_fetch_emails
    mail = poplib.POP3_SSL(self.host)
  File "/usr/local/lib/python3.8/poplib.py", line 450, in __init__
    POP3.__init__(self, host, port, timeout)
  File "/usr/local/lib/python3.8/poplib.py", line 104, in __init__
    self.sock = self._create_socket(timeout)
  File "/usr/local/lib/python3.8/poplib.py", line 453, in _create_socket
    sock = POP3._create_socket(self, timeout)
  File "/usr/local/lib/python3.8/poplib.py", line 110, in _create_socket
    return socket.create_connection((self.host, self.port), timeout)
  File "/usr/local/lib/python3.8/socket.py", line 808, in create_connection
    raise err
  File "/usr/local/lib/python3.8/socket.py", line 796, in create_connection
    sock.connect(sa)
TimeoutError: [Errno 110] Connection timed out
[2024-07-03T12:24:31.424+0000] {taskinstance.py:1400} INFO - Marking task as FAILED. dag_id=reports_workflow, task_id=id_task_get_emails, execution_date=20240702T061500, start_date=20240703T122220, end_date=20240703T122431
[2024-07-03T12:24:31.466+0000] {standard_task_runner.py:104} ERROR - Failed to execute job 1037 for task id_task_get_emails ([Errno 110] Connection timed out; 24113)
[2024-07-03T12:24:31.494+0000] {local_task_job_runner.py:228} INFO - Task exited with return code 1
[2024-07-03T12:24:31.520+0000] {taskinstance.py:2784} INFO - 0 downstream tasks scheduled from follow-on schedule check
